[32m2023-06-02 14:11:34 -0400[0m - dagster - [34mDEBUG[0m - __ASSET_JOB - 5ba94160-4b06-441e-9d3f-a2dd129fdeb0 - 66006 - LOGS_CAPTURED - Started capturing logs in process (pid: 66006).
[32m2023-06-02 14:11:34 -0400[0m - dagster - [34mDEBUG[0m - __ASSET_JOB - 5ba94160-4b06-441e-9d3f-a2dd129fdeb0 - 66006 - acsData - STEP_START - Started execution of step "acsData".
[32m2023-06-02 14:11:34 -0400[0m - dagster - [34mDEBUG[0m - __ASSET_JOB - 5ba94160-4b06-441e-9d3f-a2dd129fdeb0 - acsData - Loading file from: /Users/blakevanfleteren/Programs/GitHub/vaccine_data/vaccines/tmpbd1xor13/storage/acsURLs
[32m2023-06-02 14:11:34 -0400[0m - dagster - [34mDEBUG[0m - __ASSET_JOB - 5ba94160-4b06-441e-9d3f-a2dd129fdeb0 - 66006 - acsData - ASSET_OBSERVATION - ASSET_OBSERVATION for step acsData
[32m2023-06-02 14:11:34 -0400[0m - dagster - [34mDEBUG[0m - __ASSET_JOB - 5ba94160-4b06-441e-9d3f-a2dd129fdeb0 - 66006 - acsData - LOADED_INPUT - Loaded input "acsURLs" using input manager "io_manager"
[32m2023-06-02 14:11:34 -0400[0m - dagster - [34mDEBUG[0m - __ASSET_JOB - 5ba94160-4b06-441e-9d3f-a2dd129fdeb0 - 66006 - acsData - STEP_INPUT - Got input "acsURLs" of type "dict". (Type check passed).
[32m2023-06-02 14:11:35 -0400[0m - dagster - [34mERROR[0m - [31m__ASSET_JOB - 5ba94160-4b06-441e-9d3f-a2dd129fdeb0 - 66006 - acsData - STEP_FAILURE - Execution of step "acsData" failed.

dagster._core.errors.DagsterExecutionStepExecutionError: Error occurred while executing op "acsData"::

requests.exceptions.ConnectionError: ('Connection aborted.', ConnectionResetError(54, 'Connection reset by peer'))

Stack Trace:
  File "/Users/blakevanfleteren/Programs/GitHub/vaccine_data/.venv/lib/python3.9/site-packages/dagster/_core/execution/plan/utils.py", line 54, in op_execution_error_boundary
    yield
  File "/Users/blakevanfleteren/Programs/GitHub/vaccine_data/.venv/lib/python3.9/site-packages/dagster/_utils/__init__.py", line 445, in iterate_with_context
    next_output = next(iterator)
  File "/Users/blakevanfleteren/Programs/GitHub/vaccine_data/.venv/lib/python3.9/site-packages/dagster/_core/execution/plan/compute_generator.py", line 124, in _coerce_op_compute_fn_to_iterator
    result = invoke_compute_fn(
  File "/Users/blakevanfleteren/Programs/GitHub/vaccine_data/.venv/lib/python3.9/site-packages/dagster/_core/execution/plan/compute_generator.py", line 118, in invoke_compute_fn
    return fn(context, **args_to_pass) if context_arg_provided else fn(**args_to_pass)
  File "/Users/blakevanfleteren/Programs/GitHub/vaccine_data/vaccines/vaccines/assets.py", line 133, in acsData
    response = requests.get(url)
  File "/Users/blakevanfleteren/Programs/GitHub/vaccine_data/.venv/lib/python3.9/site-packages/requests/api.py", line 73, in get
    return request("get", url, params=params, **kwargs)
  File "/Users/blakevanfleteren/Programs/GitHub/vaccine_data/.venv/lib/python3.9/site-packages/requests/api.py", line 59, in request
    return session.request(method=method, url=url, **kwargs)
  File "/Users/blakevanfleteren/Programs/GitHub/vaccine_data/.venv/lib/python3.9/site-packages/requests/sessions.py", line 589, in request
    resp = self.send(prep, **send_kwargs)
  File "/Users/blakevanfleteren/Programs/GitHub/vaccine_data/.venv/lib/python3.9/site-packages/requests/sessions.py", line 703, in send
    r = adapter.send(request, **kwargs)
  File "/Users/blakevanfleteren/Programs/GitHub/vaccine_data/.venv/lib/python3.9/site-packages/requests/adapters.py", line 501, in send
    raise ConnectionError(err, request=request)

The above exception occurred during handling of the following exception:
urllib3.exceptions.ProtocolError: ('Connection aborted.', ConnectionResetError(54, 'Connection reset by peer'))

Stack Trace:
  File "/Users/blakevanfleteren/Programs/GitHub/vaccine_data/.venv/lib/python3.9/site-packages/requests/adapters.py", line 486, in send
    resp = conn.urlopen(
  File "/Users/blakevanfleteren/Programs/GitHub/vaccine_data/.venv/lib/python3.9/site-packages/urllib3/connectionpool.py", line 798, in urlopen
    retries = retries.increment(
  File "/Users/blakevanfleteren/Programs/GitHub/vaccine_data/.venv/lib/python3.9/site-packages/urllib3/util/retry.py", line 550, in increment
    raise six.reraise(type(error), error, _stacktrace)
  File "/Users/blakevanfleteren/Programs/GitHub/vaccine_data/.venv/lib/python3.9/site-packages/urllib3/packages/six.py", line 769, in reraise
    raise value.with_traceback(tb)
  File "/Users/blakevanfleteren/Programs/GitHub/vaccine_data/.venv/lib/python3.9/site-packages/urllib3/connectionpool.py", line 714, in urlopen
    httplib_response = self._make_request(
  File "/Users/blakevanfleteren/Programs/GitHub/vaccine_data/.venv/lib/python3.9/site-packages/urllib3/connectionpool.py", line 466, in _make_request
    six.raise_from(e, None)
  File "<string>", line 3, in raise_from
  File "/Users/blakevanfleteren/Programs/GitHub/vaccine_data/.venv/lib/python3.9/site-packages/urllib3/connectionpool.py", line 461, in _make_request
    httplib_response = conn.getresponse()
  File "/Users/blakevanfleteren/.pyenv/versions/3.9.7/lib/python3.9/http/client.py", line 1371, in getresponse
    response.begin()
  File "/Users/blakevanfleteren/.pyenv/versions/3.9.7/lib/python3.9/http/client.py", line 319, in begin
    version, status, reason = self._read_status()
  File "/Users/blakevanfleteren/.pyenv/versions/3.9.7/lib/python3.9/http/client.py", line 280, in _read_status
    line = str(self.fp.readline(_MAXLINE + 1), "iso-8859-1")
  File "/Users/blakevanfleteren/.pyenv/versions/3.9.7/lib/python3.9/socket.py", line 704, in readinto
    return self._sock.recv_into(b)
  File "/Users/blakevanfleteren/.pyenv/versions/3.9.7/lib/python3.9/ssl.py", line 1241, in recv_into
    return self.read(nbytes, buffer)
  File "/Users/blakevanfleteren/.pyenv/versions/3.9.7/lib/python3.9/ssl.py", line 1099, in read
    return self._sslobj.read(len, buffer)

The above exception occurred during handling of the following exception:
ConnectionResetError: [Errno 54] Connection reset by peer

Stack Trace:
  File "/Users/blakevanfleteren/Programs/GitHub/vaccine_data/.venv/lib/python3.9/site-packages/urllib3/connectionpool.py", line 714, in urlopen
    httplib_response = self._make_request(
  File "/Users/blakevanfleteren/Programs/GitHub/vaccine_data/.venv/lib/python3.9/site-packages/urllib3/connectionpool.py", line 466, in _make_request
    six.raise_from(e, None)
  File "<string>", line 3, in raise_from
  File "/Users/blakevanfleteren/Programs/GitHub/vaccine_data/.venv/lib/python3.9/site-packages/urllib3/connectionpool.py", line 461, in _make_request
    httplib_response = conn.getresponse()
  File "/Users/blakevanfleteren/.pyenv/versions/3.9.7/lib/python3.9/http/client.py", line 1371, in getresponse
    response.begin()
  File "/Users/blakevanfleteren/.pyenv/versions/3.9.7/lib/python3.9/http/client.py", line 319, in begin
    version, status, reason = self._read_status()
  File "/Users/blakevanfleteren/.pyenv/versions/3.9.7/lib/python3.9/http/client.py", line 280, in _read_status
    line = str(self.fp.readline(_MAXLINE + 1), "iso-8859-1")
  File "/Users/blakevanfleteren/.pyenv/versions/3.9.7/lib/python3.9/socket.py", line 704, in readinto
    return self._sock.recv_into(b)
  File "/Users/blakevanfleteren/.pyenv/versions/3.9.7/lib/python3.9/ssl.py", line 1241, in recv_into
    return self.read(nbytes, buffer)
  File "/Users/blakevanfleteren/.pyenv/versions/3.9.7/lib/python3.9/ssl.py", line 1099, in read
    return self._sslobj.read(len, buffer)

The above exception occurred during handling of the following exception:
TypeError: getresponse() got an unexpected keyword argument 'buffering'

Stack Trace:
  File "/Users/blakevanfleteren/Programs/GitHub/vaccine_data/.venv/lib/python3.9/site-packages/urllib3/connectionpool.py", line 457, in _make_request
    httplib_response = conn.getresponse(buffering=True)
[0m
